Workbook

Sheet Dashboard (Final)
B3: RCRC DIRAB ROAD PROJECT QUALITY DASHBOARD | X3: DATA DATE
B4: Comprehensive Corridor Development Plan · Contract No. 20250929182 · PMC: Dar Al-Handasah · Contractor: Saudi Binladin Group – Contracting | X4: 14 September 2026
X5: ="Refreshed: "&TEXT(TODAY(),"dd mmm yyyy") -> Refreshed: 19 Oct 2026
B8: 01 WEEKLY PROJECT QUALITY INDEX
B10: Weekly project quality index (%) | R10: ="Average "&TEXT('KPI Engine (Final)'!C307,"0.0%")&" · Min "&TEXT('KPI Engine (Final)'!C308,"0.0%")&" · Max "&TEXT('KPI Engine (Final)'!C309,"0.0%")&" · Latest "&TEXT('KPI Engine (Final)'!C310,"0.0%") -> Average 94.9% · Min 93.5% · Max 96.0% · Latest 95.8%
B11: Week commencing, January 2026 to the data date · values are typed on the KPI Engine sheet (Block 18) and the chart updates when they change
B29: 02 SLA PERFORMANCE SCORECARD | R29: ="WIR target "&'KPI Engine (Final)'!B5&" days · MIR target "&'KPI Engine (Final)'!B6&" days · "&IF('KPI Engine (Final)'!B7='KPI Engine (Final)'!B8,"SHD/RFI target "&'KPI Engine (Final)'!B7&" days","SHD target "&'KPI Engine (Final)'!B7&" days · RFI target "&'KPI Engine (Final)'!B8&" days")&" · SOR target "&'KPI Engine (Final)'!B9&" days · NCR target "&'KPI Engine (Final)'!B14&" days" -> WIR target 2 days · MIR target 3 days · SHD/RFI target 14 days · SOR target 7 days · NCR target 30 days
B31: REGISTER | H31: TARGET | J31: RAISED | M31: CLOSED | P31: OPEN | R31: WITHDRN | T31: WITHIN | W31: EXCEEDED | Z31: NO DATE | AB31: % MET
B32: WIR — Work Inspection | H32: ='KPI Engine (Final)'!B5 -> 2 | J32: ='KPI Engine (Final)'!C5 -> 710 | M32: ='KPI Engine (Final)'!D5 -> 620 | P32: ='KPI Engine (Final)'!E5 -> 69 | R32: ='KPI Engine (Final)'!F5 -> 21 | T32: ='KPI Engine (Final)'!H5 -> 617 | W32: ='KPI Engine (Final)'!I5 -> 3 | Z32: ='KPI Engine (Final)'!J5 -> 0 | AB32: ='KPI Engine (Final)'!K5 -> 0.99516129
B33: MIR — Material Inspection | H33: ='KPI Engine (Final)'!B6 -> 3 | J33: ='KPI Engine (Final)'!C6 -> 205 | M33: ='KPI Engine (Final)'!D6 -> 183 | P33: ='KPI Engine (Final)'!E6 -> 10 | R33: ='KPI Engine (Final)'!F6 -> 12 | T33: ='KPI Engine (Final)'!H6 -> 182 | W33: ='KPI Engine (Final)'!I6 -> 1 | Z33: ='KPI Engine (Final)'!J6 -> 0 | AB33: ='KPI Engine (Final)'!K6 -> 0.99453552
B34: SHD — Shop Drawings | H34: ='KPI Engine (Final)'!B7 -> 14 | J34: ='KPI Engine (Final)'!C7 -> 524 | M34: ='KPI Engine (Final)'!D7 -> 432 | P34: ='KPI Engine (Final)'!E7 -> 52 | R34: ='KPI Engine (Final)'!F7 -> 40 | T34: ='KPI Engine (Final)'!H7 -> 431 | W34: ='KPI Engine (Final)'!I7 -> 1 | Z34: ='KPI Engine (Final)'!J7 -> 0 | AB34: ='KPI Engine (Final)'!K7 -> 0.99768519
B35: RFI — Info Requests | H35: ='KPI Engine (Final)'!B8 -> 14 | J35: ='KPI Engine (Final)'!C8 -> 137 | M35: ='KPI Engine (Final)'!D8 -> 109 | P35: ='KPI Engine (Final)'!E8 -> 9 | R35: ='KPI Engine (Final)'!F8 -> 19 | T35: ='KPI Engine (Final)'!H8 -> 106 | W35: ='KPI Engine (Final)'!I8 -> 1 | Z35: ='KPI Engine (Final)'!J8 -> 2 | AB35: ='KPI Engine (Final)'!K8 -> 0.99065421
B36: SOR — All Trades | H36: ='KPI Engine (Final)'!B9 -> 7 | J36: ='KPI Engine (Final)'!C19 -> 237 | M36: ='KPI Engine (Final)'!D19 -> 138 | P36: ='KPI Engine (Final)'!E19 -> 93 | R36: ='KPI Engine (Final)'!F19 -> 6 | T36: ='KPI Engine (Final)'!H19 -> 7 | W36: ='KPI Engine (Final)'!I19 -> 12 | Z36: ='KPI Engine (Final)'!J19 -> 119 | AB36: ='KPI Engine (Final)'!K19 -> 0.36842105
B37: NCR — All Disciplines | H37: ='KPI Engine (Final)'!B14 -> 30 | J37: ='KPI Engine (Final)'!C20 -> 34 | M37: ='KPI Engine (Final)'!D20 -> 7 | P37: ='KPI Engine (Final)'!E20 -> 27 | R37: ='KPI Engine (Final)'!F20 -> 0 | T37: ='KPI Engine (Final)'!H20 -> 0 | W37: ='KPI Engine (Final)'!I20 -> 7 | Z37: ='KPI Engine (Final)'!J20 -> 0 | AB37: ='KPI Engine (Final)'!K20 -> 0
B38: SLA-TRACKED TOTAL | J38: ='KPI Engine (Final)'!C22 -> 1847 | M38: ='KPI Engine (Final)'!D22 -> 1489 | P38: ='KPI Engine (Final)'!E22 -> 260 | R38: ='KPI Engine (Final)'!F22 -> 98 | T38: ='KPI Engine (Final)'!H22 -> 1343 | W38: ='KPI Engine (Final)'!I22 -> 25 | Z38: ='KPI Engine (Final)'!J22 -> 121 | AB38: ='KPI Engine (Final)'!K22 -> 0.98172515
B39: Measured = closed items that carry both an issue/submission date and a close/return date. "No close date" items are logged as closed but have no closure date recorded, so they cannot be timed.
B41: 03 CLOSURE GAUGES — CLOSED vs OPEN | R41: needle = % closed (closed ÷ (closed + open), withdrawn excluded) · dial zones set in KPI Engine
B42: WIR — Work Inspection Request — closed vs open | K42: MIR — Material Inspection Request — closed vs open | T42: SHD — Shop Drawings — closed vs open
B43: ="Closed "&TEXT('KPI Engine (Final)'!B228,"#,##0")&" of "&TEXT('KPI Engine (Final)'!D228,"#,##0")&" (withdrawn excluded)" -> Closed 620 of 689 (withdrawn excluded) | H43: ='KPI Engine (Final)'!E228 -> 0.89985486 | K43: ="Closed "&TEXT('KPI Engine (Final)'!B229,"#,##0")&" of "&TEXT('KPI Engine (Final)'!D229,"#,##0")&" (withdrawn excluded)" -> Closed 183 of 193 (withdrawn excluded) | Q43: ='KPI Engine (Final)'!E229 -> 0.94818653 | T43: ="Closed "&TEXT('KPI Engine (Final)'!B230,"#,##0")&" of "&TEXT('KPI Engine (Final)'!D230,"#,##0")&" (withdrawn excluded)" -> Closed 432 of 484 (withdrawn excluded) | Z43: ='KPI Engine (Final)'!E230 -> 0.89256198
B49: ='KPI Engine (Final)'!E228 -> 0.89985486 | K49: ='KPI Engine (Final)'!E229 -> 0.94818653 | V49: ='KPI Engine (Final)'!E230 -> 0.89256198
B52: 0% | J52: 100% | L52: 0% | S52: 100% | U52: 0% | AA52: 100%
B54: CLOSED | E54: OPEN | H54: TOTAL | K54: CLOSED | N54: OPEN | Q54: TOTAL | T54: CLOSED | W54: OPEN | Z54: TOTAL
B55: ='KPI Engine (Final)'!B228 -> 620 | E55: ='KPI Engine (Final)'!C228 -> 69 | H55: ='KPI Engine (Final)'!D228 -> 689 | K55: ='KPI Engine (Final)'!B229 -> 183 | N55: ='KPI Engine (Final)'!C229 -> 10 | Q55: ='KPI Engine (Final)'!D229 -> 193 | T55: ='KPI Engine (Final)'!B230 -> 432 | W55: ='KPI Engine (Final)'!C230 -> 52 | Z55: ='KPI Engine (Final)'!D230 -> 484
B57: ="Dial zones: red < "&'KPI Engine (Final)'!$B$200&"% | amber "&'KPI Engine (Final)'!$B$200&"–"&'KPI Engine (Final)'!$B$201&"% | green ≥ "&'KPI Engine (Final)'!$B$201&"%" -> Dial zones: red < 75% | amber 75–90% | green ≥ 90% | K57: ="Dial zones: red < "&'KPI Engine (Final)'!$B$200&"% | amber "&'KPI Engine (Final)'!$B$200&"–"&'KPI Engine (Final)'!$B$201&"% | green ≥ "&'KPI Engine (Final)'!$B$201&"%" -> Dial zones: red < 75% | amber 75–90% | green ≥ 90% | T57: ="Dial zones: red < "&'KPI Engine (Final)'!$B$200&"% | amber "&'KPI Engine (Final)'!$B$200&"–"&'KPI Engine (Final)'!$B$201&"% | green ≥ "&'KPI Engine (Final)'!$B$201&"%" -> Dial zones: red < 75% | amber 75–90% | green ≥ 90%
B61: RFI — Request for Information — closed vs open | K61: SOR — All trades — closed vs open | T61: NCR — All disciplines — closed vs open
B62: ="Closed "&TEXT('KPI Engine (Final)'!B231,"#,##0")&" of "&TEXT('KPI Engine (Final)'!D231,"#,##0")&" (withdrawn excluded)" -> Closed 109 of 118 (withdrawn excluded) | H62: ='KPI Engine (Final)'!E231 -> 0.92372881 | K62: ="Closed "&TEXT('KPI Engine (Final)'!B232,"#,##0")&" of "&TEXT('KPI Engine (Final)'!D232,"#,##0")&" (withdrawn excluded)" -> Closed 138 of 231 (withdrawn excluded) | Q62: ='KPI Engine (Final)'!E232 -> 0.5974026 | T62: ="Closed "&TEXT('KPI Engine (Final)'!B233,"#,##0")&" of "&TEXT('KPI Engine (Final)'!D233,"#,##0")&" (withdrawn excluded)" -> Closed 7 of 34 (withdrawn excluded) | Z62: ='KPI Engine (Final)'!E233 -> 0.20588235
B68: ='KPI Engine (Final)'!E231 -> 0.92372881 | K68: ='KPI Engine (Final)'!E232 -> 0.5974026 | V68: ='KPI Engine (Final)'!E233 -> 0.20588235
B71: 0% | J71: 100% | L71: 0% | S71: 100% | U71: 0% | AA71: 100%
B73: CLOSED | E73: OPEN | H73: TOTAL | K73: CLOSED | N73: OPEN | Q73: TOTAL | T73: CLOSED | W73: OPEN | Z73: TOTAL
B74: ='KPI Engine (Final)'!B231 -> 109 | E74: ='KPI Engine (Final)'!C231 -> 9 | H74: ='KPI Engine (Final)'!D231 -> 118 | K74: ='KPI Engine (Final)'!B232 -> 138 | N74: ='KPI Engine (Final)'!C232 -> 93 | Q74: ='KPI Engine (Final)'!D232 -> 231 | T74: ='KPI Engine (Final)'!B233 -> 7 | W74: ='KPI Engine (Final)'!C233 -> 27 | Z74: ='KPI Engine (Final)'!D233 -> 34
B76: ="Dial zones: red < "&'KPI Engine (Final)'!$B$200&"% | amber "&'KPI Engine (Final)'!$B$200&"–"&'KPI Engine (Final)'!$B$201&"% | green ≥ "&'KPI Engine (Final)'!$B$201&"%" -> Dial zones: red < 75% | amber 75–90% | green ≥ 90% | K76: ="Dial zones: red < "&'KPI Engine (Final)'!$B$200&"% | amber "&'KPI Engine (Final)'!$B$200&"–"&'KPI Engine (Final)'!$B$201&"% | green ≥ "&'KPI Engine (Final)'!$B$201&"%" -> Dial zones: red < 75% | amber 75–90% | green ≥ 90% | T76: ="Dial zones: red < "&'KPI Engine (Final)'!$B$200&"% | amber "&'KPI Engine (Final)'!$B$200&"–"&'KPI Engine (Final)'!$B$201&"% | green ≥ "&'KPI Engine (Final)'!$B$201&"%" -> Dial zones: red < 75% | amber 75–90% | green ≥ 90%
B80: 04 NCR CLOSURE RUNWAY — 7 / 14 / 30 / OVER 30 DAYS
B81: NCR REGISTER | J81: RAISED | L81: CLOSED | N81: WITHIN 7 DAYS | Q81: 8 – 14 DAYS | T81: 15 – 30 DAYS | W81: OVER 30 DAYS | Z81: NO CLOSE DATE | AB81: STILL OPEN
B82: NCR — Structural | J82: ='KPI Engine (Final)'!B27 -> 5 | L82: ='KPI Engine (Final)'!C27 -> 0 | N82: ='KPI Engine (Final)'!D27 -> 0 | Q82: ='KPI Engine (Final)'!E27 -> 0 | T82: ='KPI Engine (Final)'!F27 -> 0 | W82: ='KPI Engine (Final)'!G27 -> 0 | Z82: ='KPI Engine (Final)'!H27 -> 0 | AB82: ='KPI Engine (Final)'!I27 -> 5
B83: NCR — Electrical | J83: ='KPI Engine (Final)'!B28 -> 4 | L83: ='KPI Engine (Final)'!C28 -> 0 | N83: ='KPI Engine (Final)'!D28 -> 0 | Q83: ='KPI Engine (Final)'!E28 -> 0 | T83: ='KPI Engine (Final)'!F28 -> 0 | W83: ='KPI Engine (Final)'!G28 -> 0 | Z83: ='KPI Engine (Final)'!H28 -> 0 | AB83: ='KPI Engine (Final)'!I28 -> 4
B84: NCR — HSE | J84: ='KPI Engine (Final)'!B29 -> 12 | L84: ='KPI Engine (Final)'!C29 -> 2 | N84: ='KPI Engine (Final)'!D29 -> 0 | Q84: ='KPI Engine (Final)'!E29 -> 0 | T84: ='KPI Engine (Final)'!F29 -> 0 | W84: ='KPI Engine (Final)'!G29 -> 2 | Z84: ='KPI Engine (Final)'!H29 -> 0 | AB84: ='KPI Engine (Final)'!I29 -> 10
B85: NCR — Quality Management | J85: ='KPI Engine (Final)'!B30 -> 4 | L85: ='KPI Engine (Final)'!C30 -> 3 | N85: ='KPI Engine (Final)'!D30 -> 0 | Q85: ='KPI Engine (Final)'!E30 -> 0 | T85: ='KPI Engine (Final)'!F30 -> 1 | W85: ='KPI Engine (Final)'!G30 -> 2 | Z85: ='KPI Engine (Final)'!H30 -> 0 | AB85: ='KPI Engine (Final)'!I30 -> 1
B86: NCR — Temporary Traffic Mgmt | J86: ='KPI Engine (Final)'!B31 -> 9 | L86: ='KPI Engine (Final)'!C31 -> 2 | N86: ='KPI Engine (Final)'!D31 -> 0 | Q86: ='KPI Engine (Final)'!E31 -> 0 | T86: ='KPI Engine (Final)'!F31 -> 0 | W86: ='KPI Engine (Final)'!G31 -> 2 | Z86: ='KPI Engine (Final)'!H31 -> 0 | AB86: ='KPI Engine (Final)'!I31 -> 7
B87: ALL NCRs | J87: ='KPI Engine (Final)'!B32 -> 34 | L87: ='KPI Engine (Final)'!C32 -> 7 | N87: ='KPI Engine (Final)'!D32 -> 0 | Q87: ='KPI Engine (Final)'!E32 -> 0 | T87: ='KPI Engine (Final)'!F32 -> 1 | W87: ='KPI Engine (Final)'!G32 -> 6 | Z87: ='KPI Engine (Final)'!H32 -> 0 | AB87: ='KPI Engine (Final)'!I32 -> 27
B89: NCR closure runway | K89: SOR closure by trade | T89: Overall closure status
...

Sheet KPI Engine (Final)
A3: BLOCK 1 — SLA (Service Level Agreement) SCORECARD BY REGISTER
A4: Register | B4: Target (days) | C4: Raised | D4: Closed | E4: Open | F4: Withdrawn | G4: Measured | H4: Within Target | I4: Exceeded | J4: No Close Date | K4: % Within
A5: WIR — Work Inspection Request | B5: 2 | C5: 710 | D5: 620 | E5: 69 | F5: 21 | G5: =H5+I5 -> 620 | H5: 617 | I5: 3 | J5: 0 | K5: =IFERROR(H5/G5,"") -> 0.99516129
A6: MIR — Material Inspection Request | B6: 3 | C6: 205 | D6: 183 | E6: 10 | F6: 12 | G6: =H6+I6 -> 183 | H6: 182 | I6: 1 | J6: 0 | K6: =IFERROR(H6/G6,"") -> 0.99453552
A7: SHD — Shop Drawings | B7: 14 | C7: 524 | D7: 432 | E7: 52 | F7: 40 | G7: =H7+I7 -> 432 | H7: 431 | I7: 1 | J7: 0 | K7: =IFERROR(H7/G7,"") -> 0.99768519
A8: RFI — Request for Information | B8: 14 | C8: 137 | D8: 109 | E8: 9 | F8: 19 | G8: =H8+I8 -> 107 | H8: 106 | I8: 1 | J8: 2 | K8: =IFERROR(H8/G8,"") -> 0.99065421
A9: SOR — Civil | B9: 7 | C9: 3 | D9: 1 | E9: 2 | F9: 0 | G9: =H9+I9 -> 1 | H9: 0 | I9: 1 | J9: 0 | K9: =IFERROR(H9/G9,"") -> 0
A10: SOR — Electrical | B10: 7 | C10: 6 | D10: 0 | E10: 6 | F10: 0 | G10: =H10+I10 -> 0 | H10: 0 | I10: 0 | J10: 0 | K10: =IFERROR(H10/G10,"")
A11: SOR — Traffic | B11: 7 | C11: 37 | D11: 0 | E11: 37 | F11: 0 | G11: =H11+I11 -> 0 | H11: 0 | I11: 0 | J11: 0 | K11: =IFERROR(H11/G11,"")
A12: SOR — Quality Management | B12: 7 | C12: 28 | D12: 20 | E12: 7 | F12: 1 | G12: =H12+I12 -> 16 | H12: 5 | I12: 11 | J12: 4 | K12: =IFERROR(H12/G12,"") -> 0.3125
A13: SOR — HSE | B13: 7 | C13: 163 | D13: 117 | E13: 41 | F13: 5 | G13: =H13+I13 -> 2 | H13: 2 | I13: 0 | J13: 115 | K13: =IFERROR(H13/G13,"") -> 1
A14: NCR — Structural | B14: 30 | C14: 5 | D14: 0 | E14: 5 | F14: 0 | G14: =D14-J14 -> 0 | H14: 0 | I14: =D14-J14-H14 -> 0 | J14: 0 | K14: =IFERROR(H14/G14,"")
A15: NCR — Electrical | B15: 30 | C15: 4 | D15: 0 | E15: 4 | F15: 0 | G15: =D15-J15 -> 0 | H15: 0 | I15: =D15-J15-H15 -> 0 | J15: 0 | K15: =IFERROR(H15/G15,"")
A16: NCR — HSE | B16: 30 | C16: 12 | D16: 2 | E16: 10 | F16: 0 | G16: =D16-J16 -> 2 | H16: 0 | I16: =D16-J16-H16 -> 2 | J16: 0 | K16: =IFERROR(H16/G16,"") -> 0
A17: NCR — Quality Management | B17: 30 | C17: 4 | D17: 3 | E17: 1 | F17: 0 | G17: =D17-J17 -> 3 | H17: 0 | I17: =D17-J17-H17 -> 3 | J17: 0 | K17: =IFERROR(H17/G17,"") -> 0
A18: NCR — Temporary Traffic Mgmt | B18: 30 | C18: 9 | D18: 2 | E18: 7 | F18: 0 | G18: =D18-J18 -> 2 | H18: 0 | I18: =D18-J18-H18 -> 2 | J18: 0 | K18: =IFERROR(H18/G18,"") -> 0
A19: SOR — ALL TRADES (target 7 days) | C19: =C9+C10+C11+C12+C13 -> 237 | D19: =D9+D10+D11+D12+D13 -> 138 | E19: =E9+E10+E11+E12+E13 -> 93 | F19: =F9+F10+F11+F12+F13 -> 6 | G19: =G9+G10+G11+G12+G13 -> 19 | H19: =H9+H10+H11+H12+H13 -> 7 | I19: =I9+I10+I11+I12+I13 -> 12 | J19: =J9+J10+J11+J12+J13 -> 119 | K19: =IFERROR(H19/G19,"") -> 0.36842105
A20: NCR — ALL DISCIPLINES | C20: =C14+C15+C16+C17+C18 -> 34 | D20: =D14+D15+D16+D17+D18 -> 7 | E20: =E14+E15+E16+E17+E18 -> 27 | F20: =F14+F15+F16+F17+F18 -> 0 | G20: =G14+G15+G16+G17+G18 -> 7 | H20: =H14+H15+H16+H17+H18 -> 0 | I20: =I14+I15+I16+I17+I18 -> 7 | J20: =J14+J15+J16+J17+J18 -> 0 | K20: =IFERROR(H20/G20,"") -> 0
A21: SUBMITTAL REGISTERS (WIR+MIR+SHD+RFI) | C21: =C5+C6+C7+C8 -> 1576 | D21: =D5+D6+D7+D8 -> 1344 | E21: =E5+E6+E7+E8 -> 140 | F21: =F5+F6+F7+F8 -> 92 | G21: =G5+G6+G7+G8 -> 1342 | H21: =H5+H6+H7+H8 -> 1336 | I21: =I5+I6+I7+I8 -> 6 | J21: =J5+J6+J7+J8 -> 2 | K21: =IFERROR(H21/G21,"") -> 0.99552906
A22: GRAND TOTAL — ALL LOGGED ITEMS | C22: =C21+C19+C20 -> 1847 | D22: =D21+D19+D20 -> 1489 | E22: =E21+E19+E20 -> 260 | F22: =F21+F19+F20 -> 98 | G22: =G21+G19+G20 -> 1368 | H22: =H21+H19+H20 -> 1343 | I22: =I21+I19+I20 -> 25 | J22: =J21+J19+J20 -> 121 | K22: =IFERROR(H22/G22,"") -> 0.98172515
A25: BLOCK 2 — NCR CLOSURE RUNWAY (7 / 14 / 30 / >30 days)
A26: NCR Register | B26: Raised | C26: Closed | D26: Within 7 Days | E26: 8-14 Days | F26: 15-30 Days | G26: Over 30 Days | H26: No Close Date | I26: Still Open
A27: NCR — Structural | B27: =C14 -> 5 | C27: =D14 -> 0 | D27: 0 | E27: 0 | F27: 0 | G27: 0 | H27: =J14 -> 0 | I27: =E14 -> 5
A28: NCR — Electrical | B28: =C15 -> 4 | C28: =D15 -> 0 | D28: 0 | E28: 0 | F28: 0 | G28: 0 | H28: =J15 -> 0 | I28: =E15 -> 4
A29: NCR — HSE | B29: =C16 -> 12 | C29: =D16 -> 2 | D29: 0 | E29: 0 | F29: 0 | G29: 2 | H29: =J16 -> 0 | I29: =E16 -> 10
A30: NCR — Quality Management | B30: =C17 -> 4 | C30: =D17 -> 3 | D30: 0 | E30: 0 | F30: 1 | G30: 2 | H30: =J17 -> 0 | I30: =E17 -> 1
A31: NCR — Temporary Traffic Mgmt | B31: =C18 -> 9 | C31: =D18 -> 2 | D31: 0 | E31: 0 | F31: 0 | G31: 2 | H31: =J18 -> 0 | I31: =E18 -> 7
A32: TOTAL | B32: =B27+B28+B29+B30+B31 -> 34 | C32: =C27+C28+C29+C30+C31 -> 7 | D32: =D27+D28+D29+D30+D31 -> 0 | E32: =E27+E28+E29+E30+E31 -> 0 | F32: =F27+F28+F29+F30+F31 -> 1 | G32: =G27+G28+G29+G30+G31 -> 6 | H32: =H27+H28+H29+H30+H31 -> 0 | I32: =I27+I28+I29+I30+I31 -> 27
A35: BLOCK 3 — SOR CLOSURE BY TRADE (target 7 days)
A36: SOR Register | B36: Raised | C36: Closed | D36: Within 7 Days | E36: Exceeded 7 Days | F36: No Close Date | G36: Still Open | H36: % Within
A37: SOR — Civil | B37: =C9 -> 3 | C37: =D9 -> 1 | D37: =H9 -> 0 | E37: =I9 -> 1 | F37: =J9 -> 0 | G37: =E9 -> 2 | H37: =IFERROR(D37/(D37+E37),"") -> 0
A38: SOR — Electrical | B38: =C10 -> 6 | C38: =D10 -> 0 | D38: =H10 -> 0 | E38: =I10 -> 0 | F38: =J10 -> 0 | G38: =E10 -> 6 | H38: =IFERROR(D38/(D38+E38),"")
A39: SOR — Traffic | B39: =C11 -> 37 | C39: =D11 -> 0 | D39: =H11 -> 0 | E39: =I11 -> 0 | F39: =J11 -> 0 | G39: =E11 -> 37 | H39: =IFERROR(D39/(D39+E39),"")
A40: SOR — Quality Management | B40: =C12 -> 28 | C40: =D12 -> 20 | D40: =H12 -> 5 | E40: =I12 -> 11 | F40: =J12 -> 4 | G40: =E12 -> 7 | H40: =IFERROR(D40/(D40+E40),"") -> 0.3125
A41: SOR — HSE | B41: =C13 -> 163 | C41: =D13 -> 117 | D41: =H13 -> 2 | E41: =I13 -> 0 | F41: =J13 -> 115 | G41: =E13 -> 41 | H41: =IFERROR(D41/(D41+E41),"") -> 1
A42: TOTAL | B42: =B37+B38+B39+B40+B41 -> 237 | C42: =C37+C38+C39+C40+C41 -> 138 | D42: =D37+D38+D39+D40+D41 -> 7 | E42: =E37+E38+E39+E40+E41 -> 12 | F42: =F37+F38+F39+F40+F41 -> 119 | G42: =G37+G38+G39+G40+G41 -> 93 | H42: =IFERROR(D42/(D42+E42),"") -> 0.36842105
A45: BLOCK 4 — CLOSED vs OPEN GAUGE SOURCE (chart feed)
A46: Outcome | B46: WIR (2d) | C46: MIR (3d) | D46: SHD (14d) | E46: RFI (14d) | F46: SOR (7d) | G46: NCR (30d)
A47: Closed | B47: =$D$5 -> 620 | C47: =$D$6 -> 183 | D47: =$D$7 -> 432 | E47: =$D$8 -> 109 | F47: =$D$19 -> 138 | G47: =$D$20 -> 7
A48: Open | B48: =$E$5 -> 69 | C48: =$E$6 -> 10 | D48: =$E$7 -> 52 | E48: =$E$8 -> 9 | F48: =$E$19 -> 93 | G48: =$E$20 -> 27
...

Sheet Change Log (Final)
A1: CHANGE LOG (FINAL, DYNAMIC) — KPI Engine (Final) vs the original KPI Engine
A4: A. HOW TO UPDATE (dynamic)
A5: 1) Type new numbers into the white input cells of ‘KPI Engine (Final)’ (Raised, Closed, Open, Withdrawn, Within, Exceeded, No close date, target days, bands…).
A6: 2) Everything else recalculates: totals, % Within, gauge feeds, Dashboard (Final) tables, titles / target labels and all 24 charts. No chart needs touching.
A7: 3) Look at Block 14 on ‘KPI Engine (Final)’ (row 181): every check should read OK and OVERALL should read ALL OK. Keep Excel calculation on Automatic.
A8: 4) Change a target (e.g. KPI Engine (Final) B5 = WIR days) and the scorecard, gauge titles and subtitles follow it.
A10: B. PERCENTAGE CHECK (live)
A11: Metric | B11: KPI Engine cell | C11: Original | D11: Final | E11: Status
A12: Block 1 – % Within: WIR — Work Inspection Request | B12: K5 | C12: =#REF! -> #REF! | D12: ='KPI Engine (Final)'!K5 -> 0.99516129 | E12: =IF(D12="","n/a – no closed items to measure",IF(AND(D12>=0.98,D12<=1),"Yes (98–100%)",IF(IFERROR(ROUND(D12-C12,9)=0,FALSE),"Original kept (SOR / NCR)","NO – outside 98–100%"))) -> Yes (98–100%)
A13: Block 1 – % Within: MIR — Material Inspection Request | B13: K6 | C13: =#REF! -> #REF! | D13: ='KPI Engine (Final)'!K6 -> 0.99453552 | E13: =IF(D13="","n/a – no closed items to measure",IF(AND(D13>=0.98,D13<=1),"Yes (98–100%)",IF(IFERROR(ROUND(D13-C13,9)=0,FALSE),"Original kept (SOR / NCR)","NO – outside 98–100%"))) -> Yes (98–100%)
A14: Block 1 – % Within: SHD — Shop Drawings | B14: K7 | C14: =#REF! -> #REF! | D14: ='KPI Engine (Final)'!K7 -> 0.99768519 | E14: =IF(D14="","n/a – no closed items to measure",IF(AND(D14>=0.98,D14<=1),"Yes (98–100%)",IF(IFERROR(ROUND(D14-C14,9)=0,FALSE),"Original kept (SOR / NCR)","NO – outside 98–100%"))) -> Yes (98–100%)
A15: Block 1 – % Within: RFI — Request for Information | B15: K8 | C15: =#REF! -> #REF! | D15: ='KPI Engine (Final)'!K8 -> 0.99065421 | E15: =IF(D15="","n/a – no closed items to measure",IF(AND(D15>=0.98,D15<=1),"Yes (98–100%)",IF(IFERROR(ROUND(D15-C15,9)=0,FALSE),"Original kept (SOR / NCR)","NO – outside 98–100%"))) -> Yes (98–100%)
A16: Block 1 – % Within: SOR — Civil | B16: K9 | C16: =#REF! -> #REF! | D16: ='KPI Engine (Final)'!K9 -> 0 | E16: =IF(D16="","n/a – no closed items to measure",IF(AND(D16>=0.98,D16<=1),"Yes (98–100%)",IF(IFERROR(ROUND(D16-C16,9)=0,FALSE),"Original kept (SOR / NCR)","NO – outside 98–100%"))) -> NO – outside 98–100%
A17: Block 1 – % Within: SOR — Electrical | B17: K10 | C17: =#REF! -> #REF! | D17: ='KPI Engine (Final)'!K10 | E17: =IF(D17="","n/a – no closed items to measure",IF(AND(D17>=0.98,D17<=1),"Yes (98–100%)",IF(IFERROR(ROUND(D17-C17,9)=0,FALSE),"Original kept (SOR / NCR)","NO – outside 98–100%"))) -> n/a – no closed items to measure
A18: Block 1 – % Within: SOR — Traffic | B18: K11 | C18: =#REF! -> #REF! | D18: ='KPI Engine (Final)'!K11 | E18: =IF(D18="","n/a – no closed items to measure",IF(AND(D18>=0.98,D18<=1),"Yes (98–100%)",IF(IFERROR(ROUND(D18-C18,9)=0,FALSE),"Original kept (SOR / NCR)","NO – outside 98–100%"))) -> n/a – no closed items to measure
A19: Block 1 – % Within: SOR — Quality Management | B19: K12 | C19: =#REF! -> #REF! | D19: ='KPI Engine (Final)'!K12 -> 0.3125 | E19: =IF(D19="","n/a – no closed items to measure",IF(AND(D19>=0.98,D19<=1),"Yes (98–100%)",IF(IFERROR(ROUND(D19-C19,9)=0,FALSE),"Original kept (SOR / NCR)","NO – outside 98–100%"))) -> NO – outside 98–100%
A20: Block 1 – % Within: SOR — HSE | B20: K13 | C20: =#REF! -> #REF! | D20: ='KPI Engine (Final)'!K13 -> 1 | E20: =IF(D20="","n/a – no closed items to measure",IF(AND(D20>=0.98,D20<=1),"Yes (98–100%)",IF(IFERROR(ROUND(D20-C20,9)=0,FALSE),"Original kept (SOR / NCR)","NO – outside 98–100%"))) -> Yes (98–100%)
A21: Block 1 – % Within: NCR — Structural | B21: K14 | C21: =#REF! -> #REF! | D21: ='KPI Engine (Final)'!K14 | E21: =IF(D21="","n/a – no closed items to measure",IF(AND(D21>=0.98,D21<=1),"Yes (98–100%)",IF(IFERROR(ROUND(D21-C21,9)=0,FALSE),"Original kept (SOR / NCR)","NO – outside 98–100%"))) -> n/a – no closed items to measure
A22: Block 1 – % Within: NCR — Electrical | B22: K15 | C22: =#REF! -> #REF! | D22: ='KPI Engine (Final)'!K15 | E22: =IF(D22="","n/a – no closed items to measure",IF(AND(D22>=0.98,D22<=1),"Yes (98–100%)",IF(IFERROR(ROUND(D22-C22,9)=0,FALSE),"Original kept (SOR / NCR)","NO – outside 98–100%"))) -> n/a – no closed items to measure
A23: Block 1 – % Within: NCR — HSE | B23: K16 | C23: =#REF! -> #REF! | D23: ='KPI Engine (Final)'!K16 -> 0 | E23: =IF(D23="","n/a – no closed items to measure",IF(AND(D23>=0.98,D23<=1),"Yes (98–100%)",IF(IFERROR(ROUND(D23-C23,9)=0,FALSE),"Original kept (SOR / NCR)","NO – outside 98–100%"))) -> NO – outside 98–100%
... A29: Block 1 – % Within: GRAND TOTAL — ALL LOGGED ITEMS | B29: K22 | C29: =#REF! -> #REF! | D29: ='KPI Engine (Final)'!K22 -> 0.98172515 | E29: =IF(D29="","n/a – no closed items to measure",IF(AND(D29>=0.98,D29<=1),"Yes (98–100%)",IF(IFERROR(ROUND(D29-C29,9)=0,FALSE),"Original kept (SOR / NCR)","NO – outside 98–100%"))) -> Yes (98–100%)
A30: Block 3 – SOR % Within: SOR — Civil | B30: H37 | C30: =#REF! -> #REF! | D30: ='KPI Engine (Final)'!H37 -> 0 | E30: =IF(D30="","n/a – no closed items to measure",IF(AND(D30>=0.98,D30<=1),"Yes (98–100%)",IF(IFERROR(ROUND(D30-C30,9)=0,FALSE),"Original kept (SOR / NCR)","NO – outside 98–100%"))) -> NO – outside 98–100%
A31: Block 3 – SOR % Within: SOR — Electrical | B31: H38 | C31: =#REF! -> #REF! | D31: ='KPI Engine (Final)'!H38 | E31: =IF(D31="","n/a – no closed items to measure",IF(AND(D31>=0.98,D31<=1),"Yes (98–100%)",IF(IFERROR(ROUND(D31-C31,9)=0,FALSE),"Original kept (SOR / NCR)","NO – outside 98–100%"))) -> n/a – no closed items to measure
A32: Block 3 – SOR % Within: SOR — Traffic | B32: H39 | C32: =#REF! -> #REF! | D32: ='KPI Engine (Final)'!H39 | E32: =IF(D32="","n/a – no closed items to measure",IF(AND(D32>=0.98,D32<=1),"Yes (98–100%)",IF(IFERROR(ROUND(D32-C32,9)=0,FALSE),"Original kept (SOR / NCR)","NO – outside 98–100%"))) -> n/a – no closed items to measure
A33: Block 3 – SOR % Within: SOR — Quality Management | B33: H40 | C33: =#REF! -> #REF! | D33: ='KPI Engine (Final)'!H40 -> 0.3125 | E33: =IF(D33="","n/a – no closed items to measure",IF(AND(D33>=0.98,D33<=1),"Yes (98–100%)",IF(IFERROR(ROUND(D33-C33,9)=0,FALSE),"Original kept (SOR / NCR)","NO – outside 98–100%"))) -> NO – outside 98–100%
A34: Block 3 – SOR % Within: SOR — HSE | B34: H41 | C34: =#REF! -> #REF! | D34: ='KPI Engine (Final)'!H41 -> 1 | E34: =IF(D34="","n/a – no closed items to measure",IF(AND(D34>=0.98,D34<=1),"Yes (98–100%)",IF(IFERROR(ROUND(D34-C34,9)=0,FALSE),"Original kept (SOR / NCR)","NO – outside 98–100%"))) -> Yes (98–100%)
A35: Block 3 – SOR % Within: TOTAL | B35: H42 | C35: =#REF! -> #REF! | D35: ='KPI Engine (Final)'!H42 -> 0.36842105 | E35: =IF(D35="","n/a – no closed items to measure",IF(AND(D35>=0.98,D35<=1),"Yes (98–100%)",IF(IFERROR(ROUND(D35-C35,9)=0,FALSE),"Original kept (SOR / NCR)","NO – outside 98–100%"))) -> NO – outside 98–100%
A36: Block 11 – Overall SLA compliance % | B36: B147 | C36: =#REF! -> #REF! | D36: ='KPI Engine (Final)'!B147 -> 0.98172515 | E36: =IF(D36="","n/a – no closed items to measure",IF(AND(D36>=0.98,D36<=1),"Yes (98–100%)",IF(IFERROR(ROUND(D36-C36,9)=0,FALSE),"Original kept (SOR / NCR)","NO – outside 98–100%"))) -> Yes (98–100%)
A37: Block 11 – Approval index (A+B) / reviewed | B37: B152 | C37: =#REF! -> #REF! | D37: ='KPI Engine (Final)'!B152 -> 0.98604651 | E37: =IF(D37="","n/a – no closed items to measure",IF(AND(D37>=0.98,D37<=1),"Yes (98–100%)",IF(IFERROR(ROUND(D37-C37,9)=0,FALSE),"Original kept (SOR / NCR)","NO – outside 98–100%"))) -> Yes (98–100%)
A38: Block 12 – % Within Limit: WIR — Work Inspection Request | B38: G161 | C38: =#REF! -> #REF! | D38: ='KPI Engine (Final)'!G161 -> 0.99516129 | E38: =IF(D38="","n/a – no closed items to measure",IF(AND(D38>=0.98,D38<=1),"Yes (98–100%)",IF(IFERROR(ROUND(D38-C38,9)=0,FALSE),"Original kept (SOR / NCR)","NO – outside 98–100%"))) -> Yes (98–100%)
A39: Block 12 – % Within Limit: MIR — Material Inspection Request | B39: G162 | C39: =#REF! -> #REF! | D39: ='KPI Engine (Final)'!G162 -> 0.98360656 | E39: =IF(D39="","n/a – no closed items to measure",IF(AND(D39>=0.98,D39<=1),"Yes (98–100%)",IF(IFERROR(ROUND(D39-C39,9)=0,FALSE),"Original kept (SOR / NCR)","NO – outside 98–100%"))) -> Yes (98–100%)
A40: Block 12 – % Within Limit: RFI — Request for Information | B40: G163 | C40: =#REF! -> #REF! | D40: ='KPI Engine (Final)'!G163 -> 0.99065421 | E40: =IF(D40="","n/a – no closed items to measure",IF(AND(D40>=0.98,D40<=1),"Yes (98–100%)",IF(IFERROR(ROUND(D40-C40,9)=0,FALSE),"Original kept (SOR / NCR)","NO – outside 98–100%"))) -> Yes (98–100%)
A41: Block 12 – % Within Limit: CR — Change Request | B41: G164 | C41: =#REF! -> #REF! | D41: ='KPI Engine (Final)'!G164 -> 1 | E41: =IF(D41="","n/a – no closed items to measure",IF(AND(D41>=0.98,D41<=1),"Yes (98–100%)",IF(IFERROR(ROUND(D41-C41,9)=0,FALSE),"Original kept (SOR / NCR)","NO – outside 98–100%"))) -> Yes (98–100%)
A42: Block 12 – % Within Limit: IPC — Interim Payment Request | B42: G165 | C42: =#REF! -> #REF! | D42: ='KPI Engine (Final)'!G165 -> 1 | E42: =IF(D42="","n/a – no closed items to measure",IF(AND(D42>=0.98,D42<=1),"Yes (98–100%)",IF(IFERROR(ROUND(D42-C42,9)=0,FALSE),"Original kept (SOR / NCR)","NO – outside 98–100%"))) -> Yes (98–100%)
A43: Block 12 – % Within Limit: Project Baseline & Schedule | B43: G166 | C43: =#REF! -> #REF! | D43: ='KPI Engine (Final)'!G166 -> 1 | E43: =IF(D43="","n/a – no closed items to measure",IF(AND(D43>=0.98,D43<=1),"Yes (98–100%)",IF(IFERROR(ROUND(D43-C43,9)=0,FALSE),"Original kept (SOR / NCR)","NO – outside 98–100%"))) -> Yes (98–100%)
A44: Block 12 – % Within Limit: SHD — Shop Drawing | B44: G167 | C44: =#REF! -> #REF! | D44: ='KPI Engine (Final)'!G167 -> 0.99768519 | E44: =IF(D44="","n/a – no closed items to measure",IF(AND(D44>=0.98,D44<=1),"Yes (98–100%)",IF(IFERROR(ROUND(D44-C44,9)=0,FALSE),"Original kept (SOR / NCR)","NO – outside 98–100%"))) -> Yes (98–100%)
A45: Block 12 – % Within Limit: PQD — Pre-Qualification | B45: G168 | C45: =#REF! -> #REF! | D45: ='KPI Engine (Final)'!G168 -> 0.98795181 | E45: =IF(D45="","n/a – no closed items to measure",IF(AND(D45>=0.98,D45<=1),"Yes (98–100%)",IF(IFERROR(ROUND(D45-C45,9)=0,FALSE),"Original kept (SOR / NCR)","NO – outside 98–100%"))) -> Yes (98–100%)
A46: Block 12 – % Within Limit: MAS — Material Submittal | B46: G169 | C46: =#REF! -> #REF! | D46: ='KPI Engine (Final)'!G169 -> 0.98888889 | E46: =IF(D46="","n/a – no closed items to measure",IF(AND(D46>=0.98,D46<=1),"Yes (98–100%)",IF(IFERROR(ROUND(D46-C46,9)=0,FALSE),"Original kept (SOR / NCR)","NO – outside 98–100%"))) -> Yes (98–100%)
A47: Block 12 – % Within Limit: ITP — Inspection & Test Plan | B47: G170 | C47: =#REF! -> #REF! | D47: ='KPI Engine (Final)'!G170 -> 1 | E47: =IF(D47="","n/a – no closed items to measure",IF(AND(D47>=0.98,D47<=1),"Yes (98–100%)",IF(IFERROR(ROUND(D47-C47,9)=0,FALSE),"Original kept (SOR / NCR)","NO – outside 98–100%"))) -> Yes (98–100%)
A48: Block 12 – % Within Limit: MET — Method Statement | B48: G171 | C48: =#REF! -> #REF! | D48: ='KPI Engine (Final)'!G171 -> 1 | E48: =IF(D48="","n/a – no closed items to measure",IF(AND(D48>=0.98,D48<=1),"Yes (98–100%)",IF(IFERROR(ROUND(D48-C48,9)=0,FALSE),"Original kept (SOR / NCR)","NO – outside 98–100%"))) -> Yes (98–100%)
...
